# try:
#     raise TypeError('bad type')
# except Exception as e:
#     e.add_note('Add some information')
#     e.add_note('Add some more information')
#     raise

def f():
    raise OSError('operations failed')

excs = []
for i in range(3):
    try:
        f()
    except Exception as e:
        e.add_note(f'Happened in Iteration {i+1}')
        excs.append(e)

raise ExceptionGroup('We have some problems', excs)